2025-03-26 04:10:19,445 - root - ERROR - Error calling Gemini API: 429 You exceeded your current quota, please check your plan and billing details. For more information on this error, head to: https://ai.google.dev/gemini-api/docs/rate-limits. [violations {
}
, links {
  description: "Learn more about Gemini API quotas"
  url: "https://ai.google.dev/gemini-api/docs/rate-limits"
}
, retry_delay {
  seconds: 40
}
]
2025-03-26 04:10:19,833 - root - ERROR - Error calling Gemini API: 429 You exceeded your current quota, please check your plan and billing details. For more information on this error, head to: https://ai.google.dev/gemini-api/docs/rate-limits. [violations {
}
, links {
  description: "Learn more about Gemini API quotas"
  url: "https://ai.google.dev/gemini-api/docs/rate-limits"
}
, retry_delay {
  seconds: 40
}
]
2025-03-26 04:10:20,190 - root - ERROR - Error calling Gemini API: 429 You exceeded your current quota, please check your plan and billing details. For more information on this error, head to: https://ai.google.dev/gemini-api/docs/rate-limits. [violations {
}
, links {
  description: "Learn more about Gemini API quotas"
  url: "https://ai.google.dev/gemini-api/docs/rate-limits"
}
, retry_delay {
  seconds: 39
}
]
2025-03-26 04:10:20,692 - root - ERROR - Error calling Gemini API: 429 You exceeded your current quota, please check your plan and billing details. For more information on this error, head to: https://ai.google.dev/gemini-api/docs/rate-limits. [violations {
}
, links {
  description: "Learn more about Gemini API quotas"
  url: "https://ai.google.dev/gemini-api/docs/rate-limits"
}
, retry_delay {
  seconds: 39
}
]
2025-03-26 04:10:20,722 - root - ERROR - Traceback (most recent call last):
  File "/app/web_interface.py", line 157, in upload_file
    processed, successful = await process_contacts(contacts, output_file)
  File "/app/ai_csv_transformer.py", line 187, in process_contacts
    results = await process_batch(batch, key_manager)
  File "/app/ai_csv_transformer.py", line 149, in process_batch
    results = await asyncio.gather(*tasks)
  File "/app/ai_csv_transformer.py", line 121, in generate_personalized_email
    response = client.generate_content(prompt).text
  File "/usr/local/lib/python3.9/site-packages/google/generativeai/generative_models.py", line 331, in generate_content
    response = self._client.generate_content(
  File "/usr/local/lib/python3.9/site-packages/google/ai/generativelanguage_v1beta/services/generative_service/client.py", line 835, in generate_content
    response = rpc(
  File "/usr/local/lib/python3.9/site-packages/google/api_core/gapic_v1/method.py", line 131, in __call__
    return wrapped_func(*args, **kwargs)
  File "/usr/local/lib/python3.9/site-packages/google/api_core/retry/retry_unary.py", line 293, in retry_wrapped_func
    return retry_target(
  File "/usr/local/lib/python3.9/site-packages/google/api_core/retry/retry_unary.py", line 153, in retry_target
    _retry_error_helper(
  File "/usr/local/lib/python3.9/site-packages/google/api_core/retry/retry_base.py", line 212, in _retry_error_helper
    raise final_exc from source_exc
  File "/usr/local/lib/python3.9/site-packages/google/api_core/retry/retry_unary.py", line 144, in retry_target
    result = target()
  File "/usr/local/lib/python3.9/site-packages/google/api_core/timeout.py", line 130, in func_with_timeout
    return func(*args, **kwargs)
  File "/usr/local/lib/python3.9/site-packages/google/api_core/grpc_helpers.py", line 78, in error_remapped_callable
    raise exceptions.from_grpc_error(exc) from exc
google.api_core.exceptions.ResourceExhausted: 429 You exceeded your current quota, please check your plan and billing details. For more information on this error, head to: https://ai.google.dev/gemini-api/docs/rate-limits. [violations {
}
, links {
  description: "Learn more about Gemini API quotas"
  url: "https://ai.google.dev/gemini-api/docs/rate-limits"
}
, retry_delay {
  seconds: 40
}
]

